{"name": "test_new_failure", "status": "failed", "statusDetails": {"message": "AssertionError: Intentional failure for demonstration\nassert 1 == 2", "trace": "self = <test_d1.TestAllureReportExample object at 0x0000020F1A9094B0>\n\n    def test_new_failure(self):\n        # This test will fail due to an assertion error\n>       assert 1 == 2, \"Intentional failure for demonstration\"\nE       AssertionError: Intentional failure for demonstration\nE       assert 1 == 2\n\ndummy\\test_d1.py:36: AssertionError"}, "start": 1728961932013, "stop": 1728961932014, "uuid": "44aa6e83-7ae3-4662-be4c-4286968929fc", "historyId": "432d80ea5da396117895aeeb5b61b90b", "testCaseId": "432d80ea5da396117895aeeb5b61b90b", "fullName": "dummy.test_d1.TestAllureReportExample#test_new_failure", "labels": [{"name": "tag", "value": "@pytest.mark.usefixtures('setup')"}, {"name": "parentSuite", "value": "dummy"}, {"name": "suite", "value": "test_d1"}, {"name": "subSuite", "value": "TestAllureReportExample"}, {"name": "host", "value": "BLR-REG-338464"}, {"name": "thread", "value": "21560-MainThread"}, {"name": "framework", "value": "pytest"}, {"name": "language", "value": "cpython3"}, {"name": "package", "value": "dummy.test_d1"}]}